Workbook

Sheet Sheet1
A1: player_name | B1: team | C1: games_played_season | D1: completions | E1: pass_attempts | F1: comp_pct | G1: season_passing_yards | H1: TD | I1: interception | J1: season | K1: season_average_pass_attempts | L1: season_average_passing_yards | M1: rush_attempts | N1: rushing_yards | O1: season_average_rushing_yards | P1: season_average_rush_attempts
A2: Drew Brees | B2: NOR | C2: 16 | D2: 422 | E2: 670 | F2: 63 | G2: 5177 | H2: 43 | I2: 19 | J2: 2012 | K2: =E2/C2 -> 41.875 | L2: =G2/C2 -> 323.5625 | M2: =VLOOKUP(A2, '2012'!$A:$H, 2, FALSE) -> 15 | N2: =VLOOKUP(A2, '2012'!$A:$H, 3, FALSE) -> 5 | O2: =N2/C2 -> 0.3125 | P2: =M2/C2 -> 0.9375
A3: Matthew Stafford | B3: DET | C3: 16 | D3: 435 | E3: 727 | F3: 59.8 | G3: 4967 | H3: 20 | I3: 17 | J3: 2012 | K3: =E3/C3 -> 45.4375 | L3: =G3/C3 -> 310.4375 | M3: =VLOOKUP(A3, '2012'!$A:$H, 2, FALSE) -> 35 | N3: =VLOOKUP(A3, '2012'!$A:$H, 3, FALSE) -> 126 | O3: =N3/C3 -> 7.875 | P3: =M3/C3 -> 2.1875
A4: Tony Romo | B4: DAL | C4: 16 | D4: 425 | E4: 648 | F4: 65.6 | G4: 4903 | H4: 28 | I4: 19 | J4: 2012 | K4: =E4/C4 -> 40.5 | L4: =G4/C4 -> 306.4375 | M4: =VLOOKUP(A4, '2012'!$A:$H, 2, FALSE) -> 30 | N4: =VLOOKUP(A4, '2012'!$A:$H, 3, FALSE) -> 49 | O4: =N4/C4 -> 3.0625 | P4: =M4/C4 -> 1.875
A5: Tom Brady | B5: NWE | C5: 16 | D5: 401 | E5: 637 | F5: 63 | G5: 4827 | H5: 34 | I5: 8 | J5: 2012 | K5: =E5/C5 -> 39.8125 | L5: =G5/C5 -> 301.6875 | M5: =VLOOKUP(A5, '2012'!$A:$H, 2, FALSE) -> 23 | N5: =VLOOKUP(A5, '2012'!$A:$H, 3, FALSE) -> 32 | O5: =N5/C5 -> 2 | P5: =M5/C5 -> 1.4375
A6: Matt Ryan | B6: ATL | C6: 16 | D6: 422 | E6: 615 | F6: 68.6 | G6: 4719 | H6: 32 | I6: 14 | J6: 2012 | K6: =E6/C6 -> 38.4375 | L6: =G6/C6 -> 294.9375 | M6: =VLOOKUP(A6, '2012'!$A:$H, 2, FALSE) -> 34 | N6: =VLOOKUP(A6, '2012'!$A:$H, 3, FALSE) -> 141 | O6: =N6/C6 -> 8.8125 | P6: =M6/C6 -> 2.125
A7: Peyton Manning | B7: DEN | C7: 16 | D7: 400 | E7: 583 | F7: 68.6 | G7: 4659 | H7: 37 | I7: 11 | J7: 2012 | K7: =E7/C7 -> 36.4375 | L7: =G7/C7 -> 291.1875 | M7: =VLOOKUP(A7, '2012'!$A:$H, 2, FALSE) -> 23 | N7: =VLOOKUP(A7, '2012'!$A:$H, 3, FALSE) -> 6 | O7: =N7/C7 -> 0.375 | P7: =M7/C7 -> 1.4375
A8: Andrew Luck | B8: IND | C8: 16 | D8: 339 | E8: 627 | F8: 54.1 | G8: 4374 | H8: 23 | I8: 18 | J8: 2012 | K8: =E8/C8 -> 39.1875 | L8: =G8/C8 -> 273.375 | M8: =VLOOKUP(A8, '2012'!$A:$H, 2, FALSE) -> 62 | N8: =VLOOKUP(A8, '2012'!$A:$H, 3, FALSE) -> 255 | O8: =N8/C8 -> 15.9375 | P8: =M8/C8 -> 3.875
A9: Aaron Rodgers | B9: GNB | C9: 16 | D9: 371 | E9: 552 | F9: 67.2 | G9: 4295 | H9: 39 | I9: 8 | J9: 2012 | K9: =E9/C9 -> 34.5 | L9: =G9/C9 -> 268.4375 | M9: =VLOOKUP(A9, '2012'!$A:$H, 2, FALSE) -> 54 | N9: =VLOOKUP(A9, '2012'!$A:$H, 3, FALSE) -> 259 | O9: =N9/C9 -> 16.1875 | P9: =M9/C9 -> 3.375
A10: Josh Freeman | B10: TAM | C10: 16 | D10: 306 | E10: 558 | F10: 54.8 | G10: 4065 | H10: 27 | I10: 17 | J10: 2012 | K10: =E10/C10 -> 34.875 | L10: =G10/C10 -> 254.0625 | M10: =VLOOKUP(A10, '2012'!$A:$H, 2, FALSE) -> 39 | N10: =VLOOKUP(A10, '2012'!$A:$H, 3, FALSE) -> 139 | O10: =N10/C10 -> 8.6875 | P10: =M10/C10 -> 2.4375
A11: Carson Palmer | B11: OAK | C11: 15 | D11: 345 | E11: 565 | F11: 61.1 | G11: 4018 | H11: 22 | I11: 14 | J11: 2012 | K11: =E11/C11 -> 37.666667 | L11: =G11/C11 -> 267.86667 | M11: =VLOOKUP(A11, '2012'!$A:$H, 2, FALSE) -> 18 | N11: =VLOOKUP(A11, '2012'!$A:$H, 3, FALSE) -> 36 | O11: =N11/C11 -> 2.4 | P11: =M11/C11 -> 1.2
A12: Matt Schaub | B12: HOU | C12: 16 | D12: 350 | E12: 544 | F12: 64.3 | G12: 4008 | H12: 22 | I12: 12 | J12: 2012 | K12: =E12/C12 -> 34 | L12: =G12/C12 -> 250.5 | M12: =VLOOKUP(A12, '2012'!$A:$H, 2, FALSE) -> 21 | N12: =VLOOKUP(A12, '2012'!$A:$H, 3, FALSE) -> -9 | O12: =N12/C12 -> -0.5625 | P12: =M12/C12 -> 1.3125
A13: Eli Manning | B13: NYG | C13: 16 | D13: 321 | E13: 536 | F13: 59.9 | G13: 3948 | H13: 26 | I13: 15 | J13: 2012 | K13: =E13/C13 -> 33.5 | L13: =G13/C13 -> 246.75 | M13: =VLOOKUP(A13, '2012'!$A:$H, 2, FALSE) -> 20 | N13: =VLOOKUP(A13, '2012'!$A:$H, 3, FALSE) -> 30 | O13: =N13/C13 -> 1.875 | P13: =M13/C13 -> 1.25
... A38: Brady Quinn | B38: KAN | C38: 8 | D38: 112 | E38: 197 | F38: 56.9 | G38: 1141 | H38: 2 | I38: 8 | J38: 2012 | K38: =E38/C38 -> 24.625 | L38: =G38/C38 -> 142.625 | M38: =VLOOKUP(A38, '2012'!$A:$H, 2, FALSE) -> 19 | N38: =VLOOKUP(A38, '2012'!$A:$H, 3, FALSE) -> 66 | O38: =N38/C38 -> 8.25 | P38: =M38/C38 -> 2.375
A39: Peyton Manning | B39: DEN | C39: 16 | D39: 450 | E39: 659 | F39: 68.3 | G39: 5477 | H39: 55 | I39: 10 | J39: 2013 | K39: =E39/C39 -> 41.1875 | L39: =G39/C39 -> 342.3125 | M39: =VLOOKUP(A39, '2013'!$A:$H, 2, FALSE) -> 32 | N39: =VLOOKUP(A39, '2013'!$A:$H, 3, FALSE) -> -31 | O39: =N39/C39 -> -1.9375 | P39: =M39/C39 -> 2
A40: Drew Brees | B40: NOR | C40: 16 | D40: 446 | E40: 650 | F40: 68.6 | G40: 5162 | H40: 39 | I40: 12 | J40: 2013 | K40: =E40/C40 -> 40.625 | L40: =G40/C40 -> 322.625 | M40: =VLOOKUP(A40, '2013'!$A:$H, 2, FALSE) -> 35 | N40: =VLOOKUP(A40, '2013'!$A:$H, 3, FALSE) -> 52 | O40: =N40/C40 -> 3.25 | P40: =M40/C40 -> 2.1875
A41: Matthew Stafford | B41: DET | C41: 16 | D41: 371 | E41: 634 | F41: 58.5 | G41: 4650 | H41: 29 | I41: 19 | J41: 2013 | K41: =E41/C41 -> 39.625 | L41: =G41/C41 -> 290.625 | M41: =VLOOKUP(A41, '2013'!$A:$H, 2, FALSE) -> 37 | N41: =VLOOKUP(A41, '2013'!$A:$H, 3, FALSE) -> 69 | O41: =N41/C41 -> 4.3125 | P41: =M41/C41 -> 2.3125
A42: Matt Ryan | B42: ATL | C42: 16 | D42: 439 | E42: 651 | F42: 67.4 | G42: 4515 | H42: 26 | I42: 17 | J42: 2013 | K42: =E42/C42 -> 40.6875 | L42: =G42/C42 -> 282.1875 | M42: =VLOOKUP(A42, '2013'!$A:$H, 2, FALSE) -> 17 | N42: =VLOOKUP(A42, '2013'!$A:$H, 3, FALSE) -> 55 | O42: =N42/C42 -> 3.4375 | P42: =M42/C42 -> 1.0625
A43: Philip Rivers | B43: SDG | C43: 16 | D43: 378 | E43: 544 | F43: 69.5 | G43: 4478 | H43: 32 | I43: 11 | J43: 2013 | K43: =E43/C43 -> 34 | L43: =G43/C43 -> 279.875 | M43: =VLOOKUP(A43, '2013'!$A:$H, 2, FALSE) -> 28 | N43: =VLOOKUP(A43, '2013'!$A:$H, 3, FALSE) -> 72 | O43: =N43/C43 -> 4.5 | P43: =M43/C43 -> 1.75
A44: Tom Brady | B44: NWE | C44: 16 | D44: 380 | E44: 628 | F44: 60.5 | G44: 4343 | H44: 25 | I44: 11 | J44: 2013 | K44: =E44/C44 -> 39.25 | L44: =G44/C44 -> 271.4375 | M44: =VLOOKUP(A44, '2013'!$A:$H, 2, FALSE) -> 32 | N44: =VLOOKUP(A44, '2013'!$A:$H, 3, FALSE) -> 18 | O44: =N44/C44 -> 1.125 | P44: =M44/C44 -> 2
A45: Andy Dalton | B45: CIN | C45: 16 | D45: 363 | E45: 586 | F45: 61.9 | G45: 4293 | H45: 33 | I45: 20 | J45: 2013 | K45: =E45/C45 -> 36.625 | L45: =G45/C45 -> 268.3125 | M45: =VLOOKUP(A45, '2013'!$A:$H, 2, FALSE) -> 61 | N45: =VLOOKUP(A45, '2013'!$A:$H, 3, FALSE) -> 183 | O45: =N45/C45 -> 11.4375 | P45: =M45/C45 -> 3.8125
A46: Carson Palmer | B46: ARI | C46: 16 | D46: 362 | E46: 572 | F46: 63.3 | G46: 4274 | H46: 24 | I46: 22 | J46: 2013 | K46: =E46/C46 -> 35.75 | L46: =G46/C46 -> 267.125 | M46: =VLOOKUP(A46, '2013'!$A:$H, 2, FALSE) -> 27 | N46: =VLOOKUP(A46, '2013'!$A:$H, 3, FALSE) -> 3 | O46: =N46/C46 -> 0.1875 | P46: =M46/C46 -> 1.6875
A47: Ben Roethlisberger | B47: PIT | C47: 16 | D47: 375 | E47: 584 | F47: 64.2 | G47: 4261 | H47: 28 | I47: 14 | J47: 2013 | K47: =E47/C47 -> 36.5 | L47: =G47/C47 -> 266.3125 | M47: =VLOOKUP(A47, '2013'!$A:$H, 2, FALSE) -> 27 | N47: =VLOOKUP(A47, '2013'!$A:$H, 3, FALSE) -> 99 | O47: =N47/C47 -> 6.1875 | P47: =M47/C47 -> 1.6875
A48: Ryan Tannehill | B48: MIA | C48: 16 | D48: 355 | E48: 588 | F48: 60.4 | G48: 3913 | H48: 24 | I48: 17 | J48: 2013 | K48: =E48/C48 -> 36.75 | L48: =G48/C48 -> 244.5625 | M48: =VLOOKUP(A48, '2013'!$A:$H, 2, FALSE) -> 40 | N48: =VLOOKUP(A48, '2013'!$A:$H, 3, FALSE) -> 238 | O48: =N48/C48 -> 14.875 | P48: =M48/C48 -> 2.5
A49: Joe Flacco | B49: BAL | C49: 16 | D49: 362 | E49: 614 | F49: 59 | G49: 3912 | H49: 19 | I49: 22 | J49: 2013 | K49: =E49/C49 -> 38.375 | L49: =G49/C49 -> 244.5 | M49: =VLOOKUP(A49, '2013'!$A:$H, 2, FALSE) -> 27 | N49: =VLOOKUP(A49, '2013'!$A:$H, 3, FALSE) -> 131 | O49: =N49/C49 -> 8.1875 | P49: =M49/C49 -> 1.6875
A50: Tony Romo | B50: DAL | C50: 15 | D50: 342 | E50: 535 | F50: 63.9 | G50: 3828 | H50: 31 | I50: 10 | J50: 2013 | K50: =E50/C50 -> 35.666667 | L50: =G50/C50 -> 255.2 | M50: =VLOOKUP(A50, '2013'!$A:$H, 2, FALSE) -> 20 | N50: =VLOOKUP(A50, '2013'!$A:$H, 3, FALSE) -> 38 | O50: =N50/C50 -> 2.5333333 | P50: =M50/C50 -> 1.3333333
... A88: Brian Hoyer | B88: CLE | C88: 3 | D88: 57 | E88: 96 | F88: 59.4 | G88: 615 | H88: 5 | I88: 3 | J88: 2013 | K88: =E88/C88 -> 32 | L88: =G88/C88 -> 205 | M88: =VLOOKUP(A88, '2013'!$A:$H, 2, FALSE) -> 6 | N88: =VLOOKUP(A88, '2013'!$A:$H, 3, FALSE) -> 16 | O88: =N88/C88 -> 5.3333333 | P88: =M88/C88 -> 2
A89: Drew Brees | B89: NOR | C89: 16 | D89: 456 | E89: 659 | F89: 69.2 | G89: 4952 | H89: 33 | I89: 17 | J89: 2014 | K89: =E89/C89 -> 41.1875 | L89: =G89/C89 -> 309.5 | M89: =VLOOKUP(A89, '2014'!$A:$H, 2, FALSE) -> 27 | N89: =VLOOKUP(A89, '2014'!$A:$H, 3, FALSE) -> 68 | O89: =N89/C89 -> 4.25 | P89: =M89/C89 -> 1.6875
A90: Ben Roethlisberger | B90: PIT | C90: 16 | D90: 408 | E90: 608 | F90: 67.1 | G90: 4952 | H90: 32 | I90: 9 | J90: 2014 | K90: =E90/C90 -> 38 | L90: =G90/C90 -> 309.5 | M90: =VLOOKUP(A90, '2014'!$A:$H, 2, FALSE) -> 33 | N90: =VLOOKUP(A90, '2014'!$A:$H, 3, FALSE) -> 27 | O90: =N90/C90 -> 1.6875 | P90: =M90/C90 -> 2.0625
A91: Andrew Luck | B91: IND | C91: 16 | D91: 380 | E91: 616 | F91: 61.7 | G91: 4761 | H91: 40 | I91: 16 | J91: 2014 | K91: =E91/C91 -> 38.5 | L91: =G91/C91 -> 297.5625 | M91: =VLOOKUP(A91, '2014'!$A:$H, 2, FALSE) -> 64 | N91: =VLOOKUP(A91, '2014'!$A:$H, 3, FALSE) -> 273 | O91: =N91/C91 -> 17.0625 | P91: =M91/C91 -> 4
A92: Peyton Manning | B92: DEN | C92: 16 | D92: 395 | E92: 597 | F92: 66.2 | G92: 4727 | H92: 39 | I92: 15 | J92: 2014 | K92: =E92/C92 -> 37.3125 | L92: =G92/C92 -> 295.4375 | M92: =VLOOKUP(A92, '2014'!$A:$H, 2, FALSE) -> 24 | N92: =VLOOKUP(A92, '2014'!$A:$H, 3, FALSE) -> -24 | O92: =N92/C92 -> -1.5 | P92: =M92/C92 -> 1.5
A93: Matt Ryan | B93: ATL | C93: 16 | D93: 415 | E93: 628 | F93: 66.1 | G93: 4694 | H93: 28 | I93: 14 | J93: 2014 | K93: =E93/C93 -> 39.25 | L93: =G93/C93 -> 293.375 | M93: =VLOOKUP(A93, '2014'!$A:$H, 2, FALSE) -> 29 | N93: =VLOOKUP(A93, '2014'!$A:$H, 3, FALSE) -> 145 | O93: =N93/C93 -> 9.0625 | P93: =M93/C93 -> 1.8125
A94: Eli Manning | B94: NYG | C94: 16 | D94: 379 | E94: 601 | F94: 63.1 | G94: 4410 | H94: 30 | I94: 14 | J94: 2014 | K94: =E94/C94 -> 37.5625 | L94: =G94/C94 -> 275.625 | M94: =VLOOKUP(A94, '2014'!$A:$H, 2, FALSE) -> 12 | N94: =VLOOKUP(A94, '2014'!$A:$H, 3, FALSE) -> 31 | O94: =N94/C94 -> 1.9375 | P94: =M94/C94 -> 0.75
A95: Aaron Rodgers | B95: GNB | C95: 16 | D95: 341 | E95: 520 | F95: 65.6 | G95: 4381 | H95: 38 | I95: 5 | J95: 2014 | K95: =E95/C95 -> 32.5 | L95: =G95/C95 -> 273.8125 | M95: =VLOOKUP(A95, '2014'!$A:$H, 2, FALSE) -> 43 | N95: =VLOOKUP(A95, '2014'!$A:$H, 3, FALSE) -> 269 | O95: =N95/C95 -> 16.8125 | P95: =M95/C95 -> 2.6875
A96: Philip Rivers | B96: SDG | C96: 16 | D96: 379 | E96: 570 | F96: 66.5 | G96: 4286 | H96: 31 | I96: 18 | J96: 2014 | K96: =E96/C96 -> 35.625 | L96: =G96/C96 -> 267.875 | M96: =VLOOKUP(A96, '2014'!$A:$H, 2, FALSE) -> 37 | N96: =VLOOKUP(A96, '2014'!$A:$H, 3, FALSE) -> 102 | O96: =N96/C96 -> 6.375 | P96: =M96/C96 -> 2.3125
A97: Matthew Stafford | B97: DET | C97: 16 | D97: 363 | E97: 602 | F97: 60.3 | G97: 4257 | H97: 22 | I97: 12 | J97: 2014 | K97: =E97/C97 -> 37.625 | L97: =G97/C97 -> 266.0625 | M97: =VLOOKUP(A97, '2014'!$A:$H, 2, FALSE) -> 43 | N97: =VLOOKUP(A97, '2014'!$A:$H, 3, FALSE) -> 93 | O97: =N97/C97 -> 5.8125 | P97: =M97/C97 -> 2.6875
A98: Tom Brady | B98: NWE | C98: 16 | D98: 373 | E98: 582 | F98: 64.1 | G98: 4109 | H98: 33 | I98: 9 | J98: 2014 | K98: =E98/C98 -> 36.375 | L98: =G98/C98 -> 256.8125 | M98: =VLOOKUP(A98, '2014'!$A:$H, 2, FALSE) -> 36 | N98: =VLOOKUP(A98, '2014'!$A:$H, 3, FALSE) -> 57 | O98: =N98/C98 -> 3.5625 | P98: =M98/C98 -> 2.25
A99: Ryan Tannehill | B99: MIA | C99: 16 | D99: 392 | E99: 590 | F99: 66.4 | G99: 4045 | H99: 27 | I99: 12 | J99: 2014 | K99: =E99/C99 -> 36.875 | L99: =G99/C99 -> 252.8125 | M99: =VLOOKUP(A99, '2014'!$A:$H, 2, FALSE) -> 56 | N99: =VLOOKUP(A99, '2014'!$A:$H, 3, FALSE) -> 311 | O99: =N99/C99 -> 19.4375 | P99: =M99/C99 -> 3.5
A100: Joe Flacco | B100: BAL | C100: 16 | D100: 344 | E100: 554 | F100: 62.1 | G100: 3986 | H100: 27 | I100: 12 | J100: 2014 | K100: =E100/C100 -> 34.625 | L100: =G100/C100 -> 249.125 | M100: =VLOOKUP(A100, '2014'!$A:$H, 2, FALSE) -> 39 | N100: =VLOOKUP(A100, '2014'!$A:$H, 3, FALSE) -> 70 | O100: =N100/C100 -> 4.375 | P100: =M100/C100 -> 2.4375
... A131: Michael Vick | B131: NYJ | C131: 3 | D131: 64 | E131: 121 | F131: 52.9 | G131: 604 | H131: 3 | I131: 2 | J131: 2014 | K131: =E131/C131 -> 40.333333 | L131: =G131/C131 -> 201.33333 | M131: =VLOOKUP(A131, '2014'!$A:$H, 2, FALSE) -> 26 | N131: =VLOOKUP(A131, '2014'!$A:$H, 3, FALSE) -> 153 | O131: =N131/C131 -> 51 | P131: =M131/C131 -> 8.6666667
...

Sheet 2024
A1: Player | B1: Att | C1: Yds | D1: TD
A2: Saquon Barkley | B2: 345 | C2: 2005 | D2: 13
A3: Derrick Henry | B3: 325 | C3: 1921 | D3: 16
A4: Kyren Williams | B4: 316 | C4: 1299 | D4: 14
A5: Bijan Robinson | B5: 304 | C5: 1456 | D5: 14
A6: Jonathan Taylor | B6: 303 | C6: 1431 | D6: 11
A7: Josh Jacobs | B7: 301 | C7: 1329 | D7: 15
A8: Najee Harris | B8: 263 | C8: 1043 | D8: 6
A9: Tony Pollard | B9: 260 | C9: 1079 | D9: 5
A10: Aaron Jones | B10: 255 | C10: 1138 | D10: 5
A11: D'Andre Swift | B11: 253 | C11: 959 | D11: 6
A12: Jahmyr Gibbs | B12: 250 | C12: 1412 | D12: 16
A13: Chuba Hubbard | B13: 250 | C13: 1195 | D13: 10
... A26: Tyrone Tracy Jr. | B26: 192 | C26: 839 | D26: 5
A27: Rushing
A28: Player | B28: Att | C28: Yds | D28: TD
A29: Brian Robinson Jr. | B29: 187 | C29: 799 | D29: 8
A30: David Montgomery | B30: 185 | C30: 775 | D30: 12
A31: Tank Bigsby | B31: 168 | C31: 766 | D31: 7
A32: Jordan Mason | B32: 153 | C32: 789 | D32: 3
A33: Kenneth Walker III | B33: 153 | C33: 573 | D33: 7
A34: Travis Etienne | B34: 150 | C34: 558 | D34: 2
A35: Jalen Hurts | B35: 150 | C35: 630 | D35: 14
A36: Jayden Daniels | B36: 148 | C36: 891 | D36: 6
A37: Rachaad White | B37: 144 | C37: 613 | D37: 3
A38: Lamar Jackson | B38: 139 | C38: 915 | D38: 4
A39: Javonte Williams | B39: 139 | C39: 513 | D39: 4
A40: Tyler Allgeier | B40: 137 | C40: 644 | D40: 3
... A53: Josh Allen | B53: 102 | C53: 531 | D53: 12
A54: Rushing
A55: Player | B55: Att | C55: Yds | D55: TD
A56: Nick Chubb | B56: 102 | C56: 332 | D56: 3
A57: Gus Edwards | B57: 101 | C57: 365 | D57: 4
A58: Braelon Allen | B58: 92 | C58: 334 | D58: 2
A59: Bo Nix | B59: 92 | C59: 430 | D59: 4
A60: Anthony Richardson | B60: 86 | C60: 499 | D60: 6
A61: Raheem Mostert | B61: 85 | C61: 278 | D61: 2
A62: Isaac Guerendo | B62: 84 | C62: 420 | D62: 4
A63: Tyjae Spears | B63: 84 | C63: 312 | D63: 4
A64: Isiah Pacheco | B64: 83 | C64: 310 | D64: 1
...

Sheet 2023
A1: Player | B1: Att | C1: Yds | D1: TD
A2: Derrick Henry | B2: 280 | C2: 1167 | D2: 12
A3: Christian McCaffrey | B3: 272 | C3: 1459 | D3: 14
A4: Rachaad White | B4: 272 | C4: 990 | D4: 6
A5: Travis Etienne | B5: 267 | C5: 1008 | D5: 11
A6: Joe Mixon | B6: 257 | C6: 1034 | D6: 9
A7: Najee Harris | B7: 255 | C7: 1035 | D7: 8
A8: Tony Pollard | B8: 252 | C8: 1005 | D8: 6
A9: Saquon Barkley | B9: 247 | C9: 962 | D9: 6
A10: Chuba Hubbard | B10: 238 | C10: 902 | D10: 5
A11: James Cook | B11: 237 | C11: 1122 | D11: 2
A12: Josh Jacobs | B12: 233 | C12: 805 | D12: 6
A13: D'Andre Swift | B13: 229 | C13: 1049 | D13: 5
... A26: Tyler Allgeier | B26: 186 | C26: 683 | D26: 4
A27: Rushing
A28: Player | B28: Att | C28: Yds | D28: TD
A29: Ezekiel Elliott | B29: 184 | C29: 642 | D29: 3
A30: Zack Moss | B30: 183 | C30: 794 | D30: 5
A31: Jahmyr Gibbs | B31: 182 | C31: 945 | D31: 10
A32: Alvin Kamara | B32: 180 | C32: 694 | D32: 5
A33: Alexander Mattison | B33: 180 | C33: 700 | D33: 0
A34: Austin Ekeler | B34: 179 | C34: 628 | D34: 5
A35: AJ Dillon | B35: 178 | C35: 613 | D35: 2
A36: Brian Robinson Jr. | B36: 178 | C36: 733 | D36: 5
A37: Jonathan Taylor | B37: 169 | C37: 741 | D37: 7
A38: Jalen Hurts | B38: 157 | C38: 605 | D38: 15
A39: Rhamondre Stevenson | B39: 156 | C39: 619 | D39: 4
A40: Jaylen Warren | B40: 149 | C40: 784 | D40: 4
... A53: Zamir White | B53: 104 | C53: 451 | D53: 1
A54: Rushing
A55: Player | B55: Att | C55: Yds | D55: TD
A56: De'Von Achane | B56: 103 | C56: 800 | D56: 8
A57: Ty Chandler | B57: 102 | C57: 461 | D57: 3
A58: Tyjae Spears | B58: 100 | C58: 453 | D58: 2
A59: Rico Dowdle | B59: 89 | C59: 361 | D59: 2
A60: Kenneth Gainwell | B60: 84 | C60: 364 | D60: 2
A61: Justice Hill | B61: 84 | C61: 387 | D61: 3
A62: Taysom Hill | B62: 81 | C62: 401 | D62: 4
A63: Roschon Johnson | B63: 81 | C63: 352 | D63: 2
A64: Russell Wilson | B64: 80 | C64: 341 | D64: 3
...

Sheet 2022
A1: Rushing
A2: Player | B2: Att | C2: Yds | D2: TD
A3: Derrick Henry | B3: 349 | C3: 1538 | D3: 13
A4: Josh Jacobs | B4: 340 | C4: 1653 | D4: 12
A5: Nick Chubb | B5: 302 | C5: 1525 | D5: 12
A6: Saquon Barkley | B6: 295 | C6: 1312 | D6: 10
A7: Najee Harris | B7: 272 | C7: 1034 | D7: 7
A8: Dalvin Cook | B8: 264 | C8: 1173 | D8: 8
A9: Jamaal Williams | B9: 262 | C9: 1066 | D9: 17
A10: Miles Sanders | B10: 259 | C10: 1269 | D10: 11
A11: Christian McCaffrey | B11: 244 | C11: 1139 | D11: 8
A12: Christian McCaffrey | B12: 85 | C12: 393 | D12: 2
A13: Christian McCaffrey | B13: 159 | C13: 746 | D13: 6
A14: Ezekiel Elliott | B14: 231 | C14: 876 | D14: 12
... A27: Tony Pollard | B27: 193 | C27: 1007 | D27: 9
A28: Rushing
A29: Player | B29: Att | C29: Yds | D29: TD
A30: Jonathan Taylor | B30: 192 | C30: 861 | D30: 4
A31: Leonard Fournette | B31: 189 | C31: 668 | D31: 3
A32: Cam Akers | B32: 188 | C32: 786 | D32: 7
A33: AJ Dillon | B33: 186 | C33: 770 | D33: 7
A34: James Conner | B34: 183 | C34: 782 | D34: 7
A35: Raheem Mostert | B35: 181 | C35: 891 | D35: 3
A36: Devin Singletary | B36: 177 | C36: 819 | D36: 5
A37: Jeff Wilson | B37: 176 | C37: 860 | D37: 5
A38: Jeff Wilson | B38: 92 | C38: 468 | D38: 2
A39: Jeff Wilson | B39: 84 | C39: 392 | D39: 3
A40: Latavius Murray | B40: 171 | C40: 760 | D40: 6
A41: Latavius Murray | B41: 11 | C41: 57 | D41: 1
... A54: Lamar Jackson | B54: 112 | C54: 764 | D54: 3
A55: Rushing
A56: Player | B56: Att | C56: Yds | D56: TD
A57: James Robinson | B57: 110 | C57: 425 | D57: 3
A58: James Robinson | B58: 81 | C58: 340 | D58: 3
A59: James Robinson | B59: 29 | C59: 85 | D59: 0
A60: Kenyan Drake | B60: 109 | C60: 482 | D60: 4
A61: Damien Harris | B61: 106 | C61: 462 | D61: 3
A62: D'Andre Swift | B62: 99 | C62: 542 | D62: 5
A63: Taysom Hill | B63: 96 | C63: 575 | D63: 7
A64: Chuba Hubbard | B64: 95 | C64: 466 | D64: 2
...

Sheet 2021
A1: Player | B1: Att | C1: Yds | D1: TD
A2: Jonathan Taylor | B2: 332 | C2: 1811 | D2: 18
A3: Najee Harris | B3: 307 | C3: 1200 | D3: 7
A4: Joe Mixon | B4: 292 | C4: 1205 | D4: 13
A5: Antonio Gibson | B5: 258 | C5: 1037 | D5: 7
A6: Dalvin Cook | B6: 249 | C6: 1159 | D6: 6
A7: Alvin Kamara | B7: 240 | C7: 898 | D7: 4
A8: Ezekiel Elliott | B8: 237 | C8: 1002 | D8: 10
A9: Nick Chubb | B9: 228 | C9: 1259 | D9: 8
A10: David Montgomery | B10: 225 | C10: 849 | D10: 7
A11: Derrick Henry | B11: 219 | C11: 937 | D11: 10
A12: Josh Jacobs | B12: 217 | C12: 872 | D12: 9
A13: Sony Michel | B13: 208 | C13: 845 | D13: 4
... A26: James Robinson | B26: 164 | C26: 767 | D26: 8
A27: Rushing
A28: Player | B28: Att | C28: Yds | D28: TD
A29: Saquon Barkley | B29: 162 | C29: 593 | D29: 2
A30: Mark Ingram | B30: 160 | C30: 554 | D30: 2
A31: Mark Ingram | B31: 92 | C31: 294 | D31: 1
A32: Mark Ingram | B32: 68 | C32: 260 | D32: 1
A33: Cordarrelle Patterson | B33: 153 | C33: 618 | D33: 6
A34: Jamaal Williams | B34: 153 | C34: 601 | D34: 3
A35: D'Andre Swift | B35: 151 | C35: 617 | D35: 5
A36: Darrell Henderson | B36: 149 | C36: 688 | D36: 5
A37: Michael Carter | B37: 147 | C37: 639 | D37: 4
A38: Devontae Booker | B38: 145 | C38: 593 | D38: 2
A39: Darrel Williams | B39: 144 | C39: 558 | D39: 6
A40: Jalen Hurts | B40: 139 | C40: 784 | D40: 10
... A53: Rashaad Penny | B53: 119 | C53: 749 | D53: 6
A54: Rushing
A55: Player | B55: Att | C55: Yds | D55: TD
A56: Chase Edmonds | B56: 116 | C56: 592 | D56: 2
A57: Alex Collins | B57: 108 | C57: 411 | D57: 2
A58: Khalil Herbert | B58: 103 | C58: 433 | D58: 2
A59: Ronald Jones II | B59: 101 | C59: 428 | D59: 4
A60: D'Ernest Johnson | B60: 100 | C60: 534 | D60: 3
A61: Christian McCaffrey | B61: 99 | C61: 442 | D61: 1
A62: Zack Moss | B62: 96 | C62: 345 | D62: 4
A63: Kyler Murray | B63: 88 | C63: 423 | D63: 5
A64: Phillip Lindsay | B64: 88 | C64: 249 | D64: 1
...

Sheet 2020
A1: Player | B1: Att | C1: Yds | D1: TD
A2: Derrick Henry | B2: 378 | C2: 2027 | D2: 17
A3: Dalvin Cook | B3: 312 | C3: 1557 | D3: 16
A4: Josh Jacobs | B4: 273 | C4: 1065 | D4: 12
A5: David Montgomery | B5: 247 | C5: 1070 | D5: 8
A6: Ezekiel Elliott | B6: 244 | C6: 979 | D6: 6
A7: James Robinson | B7: 240 | C7: 1070 | D7: 7
A8: Kenyan Drake | B8: 239 | C8: 955 | D8: 10
A9: Jonathan Taylor | B9: 232 | C9: 1169 | D9: 11
A10: Melvin Gordon | B10: 215 | C10: 986 | D10: 9
A11: Aaron Jones | B11: 201 | C11: 1104 | D11: 9
A12: Kareem Hunt | B12: 198 | C12: 841 | D12: 6
A13: Todd Gurley | B13: 195 | C13: 678 | D13: 9
... A26: Wayne Gallman | B26: 147 | C26: 682 | D26: 6
A27: Rushing
A28: Player | B28: Att | C28: Yds | D28: TD
A29: David Johnson | B29: 147 | C29: 691 | D29: 6
A30: Latavius Murray | B30: 146 | C30: 656 | D30: 4
A31: Cam Akers | B31: 145 | C31: 625 | D31: 2
A32: Gus Edwards | B32: 144 | C32: 723 | D32: 6
A33: Myles Gaskin | B33: 142 | C33: 584 | D33: 3
A34: Chris Carson | B34: 141 | C34: 681 | D34: 5
A35: Darrell Henderson | B35: 138 | C35: 624 | D35: 5
A36: Damien Harris | B36: 137 | C36: 691 | D36: 2
A37: Cam Newton | B37: 137 | C37: 592 | D37: 12
A38: J.K. Dobbins | B38: 134 | C38: 805 | D38: 9
A39: Kyler Murray | B39: 133 | C39: 819 | D39: 11
A40: Jeff Wilson | B40: 126 | C40: 600 | D40: 7
... A53: Tony Pollard | B53: 101 | C53: 435 | D53: 4
A54: Rushing
A55: Player | B55: Att | C55: Yds | D55: TD
A56: Brian Hill | B56: 100 | C56: 465 | D56: 1
A57: Chase Edmonds | B57: 97 | C57: 448 | D57: 1
A58: Leonard Fournette | B58: 97 | C58: 367 | D58: 6
A59: Alexander Mattison | B59: 96 | C59: 434 | D59: 2
A60: Peyton Barber | B60: 94 | C60: 258 | D60: 4
A61: Devontae Booker | B61: 93 | C61: 423 | D61: 3
A62: Kalen Ballage | B62: 91 | C62: 303 | D62: 3
A63: Kalen Ballage | B63: 3 | C63: 13 | D63: 0
A64: Kalen Ballage | B64: 88 | C64: 290 | D64: 3
...

Sheet 2019
A1: Player | B1: Att | C1: Yds | D1: TD
A2: Derrick Henry | B2: 303 | C2: 1540 | D2: 16
A3: Ezekiel Elliott | B3: 301 | C3: 1357 | D3: 12
A4: Nick Chubb | B4: 298 | C4: 1494 | D4: 8
A5: Christian McCaffrey | B5: 287 | C5: 1387 | D5: 15
A6: Chris Carson | B6: 278 | C6: 1230 | D6: 7
A7: Joe Mixon | B7: 278 | C7: 1137 | D7: 5
A8: Leonard Fournette | B8: 265 | C8: 1152 | D8: 3
A9: Dalvin Cook | B9: 250 | C9: 1135 | D9: 13
A10: Marlon Mack | B10: 247 | C10: 1091 | D10: 8
A11: Sony Michel | B11: 247 | C11: 912 | D11: 7
A12: Le'Veon Bell | B12: 245 | C12: 789 | D12: 3
A13: Carlos Hyde | B13: 245 | C13: 1070 | D13: 6
... A26: Alvin Kamara | B26: 171 | C26: 797 | D26: 5
A27: Rushing
A28: Player | B28: Att | C28: Yds | D28: TD
A29: Kenyan Drake | B29: 170 | C29: 817 | D29: 8
A30: Kenyan Drake | B30: 47 | C30: 174 | D30: 0
A31: Kenyan Drake | B31: 123 | C31: 643 | D31: 8
A32: Frank Gore | B32: 166 | C32: 599 | D32: 2
A33: Melvin Gordon | B33: 162 | C33: 612 | D33: 8
A34: Peyton Barber | B34: 154 | C34: 470 | D34: 6
A35: Devin Singletary | B35: 151 | C35: 775 | D35: 2
A36: Latavius Murray | B36: 146 | C36: 637 | D36: 5
A37: Tevin Coleman | B37: 137 | C37: 544 | D37: 6
A38: Raheem Mostert | B38: 137 | C38: 772 | D38: 8
A39: Gus Edwards | B39: 133 | C39: 711 | D39: 2
A40: Austin Ekeler | B40: 132 | C40: 557 | D40: 3
... A53: David Johnson | B53: 94 | C53: 345 | D53: 2
A54: Rushing
A55: Player | B55: Att | C55: Yds | D55: TD
A56: Kyler Murray | B56: 93 | C56: 544 | D56: 4
A57: Bo Scarbrough | B57: 89 | C57: 377 | D57: 1
A58: Tony Pollard | B58: 86 | C58: 455 | D58: 2
A59: Duke Johnson | B59: 83 | C59: 410 | D59: 2
A60: Deshaun Watson | B60: 82 | C60: 413 | D60: 7
A61: Brian Hill | B61: 78 | C61: 323 | D61: 2
A62: Russell Wilson | B62: 75 | C62: 342 | D62: 3
A63: Kalen Ballage | B63: 74 | C63: 135 | D63: 3
A64: Malcolm Brown | B64: 69 | C64: 255 | D64: 5
...

Sheet 2018
A1: Player | B1: Att | C1: Yds | D1: TD
A2: Ezekiel Elliott | B2: 304 | C2: 1434 | D2: 6
A3: Saquon Barkley | B3: 261 | C3: 1307 | D3: 11
A4: David Johnson | B4: 258 | C4: 940 | D4: 7
A5: Todd Gurley | B5: 256 | C5: 1251 | D5: 17
A6: Adrian Peterson | B6: 251 | C6: 1042 | D6: 7
A7: Jordan Howard | B7: 250 | C7: 935 | D7: 9
A8: Chris Carson | B8: 247 | C8: 1151 | D8: 9
A9: Joe Mixon | B9: 237 | C9: 1168 | D9: 8
A10: Peyton Barber | B10: 234 | C10: 871 | D10: 5
A11: Christian McCaffrey | B11: 219 | C11: 1098 | D11: 7
A12: James Conner | B12: 215 | C12: 973 | D12: 12
A13: Derrick Henry | B13: 215 | C13: 1059 | D13: 12
... A26: Tevin Coleman | B26: 167 | C26: 800 | D26: 4
A27: Rushing
A28: Player | B28: Att | C28: Yds | D28: TD
A29: LeSean McCoy | B29: 161 | C29: 514 | D29: 3
A30: Frank Gore | B30: 156 | C30: 722 | D30: 0
A31: Dion Lewis | B31: 155 | C31: 517 | D31: 1
A32: LeGarrette Blount | B32: 154 | C32: 418 | D32: 5
A33: Matt Breida | B33: 153 | C33: 814 | D33: 3
A34: Alfred Blue | B34: 150 | C34: 499 | D34: 2
A35: Lamar Jackson | B35: 147 | C35: 695 | D35: 5
A36: Isaiah Crowell | B36: 143 | C36: 685 | D36: 6
A37: Latavius Murray | B37: 140 | C37: 578 | D37: 6
A38: Mark Ingram | B38: 138 | C38: 645 | D38: 6
A39: Gus Edwards | B39: 137 | C39: 718 | D39: 2
A40: Dalvin Cook | B40: 133 | C40: 615 | D40: 2
... A53: T.J. Yeldon | B53: 104 | C53: 414 | D53: 1
A54: Rushing
A55: Player | B55: Att | C55: Yds | D55: TD
A56: Cam Newton | B56: 101 | C56: 488 | D56: 4
A57: Tarik Cohen | B57: 99 | C57: 444 | D57: 3
A58: Deshaun Watson | B58: 99 | C58: 551 | D58: 5
A59: James White | B59: 94 | C59: 425 | D59: 5
A60: Elijah McGuire | B60: 92 | C60: 276 | D60: 3
A61: Marshawn Lynch | B61: 90 | C61: 376 | D61: 3
A62: Ito Smith | B62: 90 | C62: 315 | D62: 4
A63: Josh Allen | B63: 89 | C63: 631 | D63: 8
A64: Wendell Smallwood | B64: 87 | C64: 364 | D64: 3
...

Sheet 2017
A1: Player | B1: Att | C1: Yds | D1: TD
A2: Le'Veon Bell | B2: 321 | C2: 1291 | D2: 9
A3: LeSean McCoy | B3: 287 | C3: 1138 | D3: 6
A4: Melvin Gordon | B4: 284 | C4: 1105 | D4: 8
A5: Todd Gurley | B5: 279 | C5: 1305 | D5: 13
A6: Jordan Howard | B6: 276 | C6: 1122 | D6: 9
A7: Kareem Hunt | B7: 272 | C7: 1327 | D7: 8
A8: Leonard Fournette | B8: 268 | C8: 1040 | D8: 9
A9: Frank Gore | B9: 261 | C9: 961 | D9: 3
A10: C.J. Anderson | B10: 245 | C10: 1007 | D10: 3
A11: Ezekiel Elliott | B11: 242 | C11: 983 | D11: 7
A12: Carlos Hyde | B12: 240 | C12: 938 | D12: 8
A13: Lamar Miller | B13: 238 | C13: 888 | D13: 3
... A26: Joe Mixon | B26: 178 | C26: 626 | D26: 4
A27: Rushing
A28: Player | B28: Att | C28: Yds | D28: TD
A29: Bilal Powell | B29: 178 | C29: 772 | D29: 5
A30: Derrick Henry | B30: 176 | C30: 744 | D30: 5
A31: Samaje Perine | B31: 175 | C31: 603 | D31: 1
A32: LeGarrette Blount | B32: 173 | C32: 766 | D32: 2
A33: Orleans Darkwa | B33: 171 | C33: 751 | D33: 5
A34: Ameer Abdullah | B34: 165 | C34: 552 | D34: 4
A35: Tevin Coleman | B35: 156 | C35: 628 | D35: 5
A36: Adrian Peterson | B36: 156 | C36: 529 | D36: 2
A37: Adrian Peterson | B37: 27 | C37: 81 | D37: 0
A38: Adrian Peterson | B38: 129 | C38: 448 | D38: 2
A39: Javorius Allen | B39: 153 | C39: 591 | D39: 4
A40: Jamaal Williams | B40: 153 | C40: 556 | D40: 4
... A53: Matt Breida | B53: 105 | C53: 465 | D53: 2
A54: Rushing
A55: Player | B55: Att | C55: Yds | D55: TD
A56: Mike Gillislee | B56: 104 | C56: 383 | D56: 5
A57: Matt Forte | B57: 103 | C57: 381 | D57: 2
A58: Russell Wilson | B58: 95 | C58: 586 | D58: 3
A59: Marlon Mack | B59: 93 | C59: 358 | D59: 3
A60: Elijah McGuire | B60: 88 | C60: 315 | D60: 1
A61: Tarik Cohen | B61: 87 | C61: 370 | D61: 2
A62: Theo Riddick | B62: 84 | C62: 286 | D62: 3
A63: Tyrod Taylor | B63: 84 | C63: 427 | D63: 4
A64: Duke Johnson | B64: 82 | C64: 348 | D64: 4
...

Sheet 2016
A1: Player | B1: Att | C1: Yds | D1: TD
A2: Ezekiel Elliott | B2: 322 | C2: 1631 | D2: 15
A3: LeGarrette Blount | B3: 299 | C3: 1161 | D3: 18
A4: David Johnson | B4: 293 | C4: 1239 | D4: 16
A5: DeMarco Murray | B5: 293 | C5: 1287 | D5: 9
A6: Todd Gurley | B6: 278 | C6: 885 | D6: 6
A7: Lamar Miller | B7: 268 | C7: 1073 | D7: 5
A8: Frank Gore | B8: 263 | C8: 1025 | D8: 4
A9: Le'Veon Bell | B9: 261 | C9: 1268 | D9: 7
A10: Jay Ajayi | B10: 260 | C10: 1272 | D10: 8
A11: Melvin Gordon | B11: 254 | C11: 997 | D11: 10
A12: Jordan Howard | B12: 252 | C12: 1313 | D12: 6
A13: LeSean McCoy | B13: 234 | C13: 1267 | D13: 13
... A26: Robert Kelley | B26: 168 | C26: 704 | D26: 6
A27: Rushing
A28: Player | B28: Att | C28: Yds | D28: TD
A29: Jerick McKinnon | B29: 159 | C29: 539 | D29: 2
A30: Ryan Mathews | B30: 155 | C30: 661 | D30: 8
A31: Christine Michael | B31: 148 | C31: 583 | D31: 7
A32: Christine Michael | B32: 117 | C32: 469 | D32: 6
A33: Christine Michael | B33: 31 | C33: 114 | D33: 1
A34: Doug Martin | B34: 144 | C34: 421 | D34: 3
A35: Tim Hightower | B35: 133 | C35: 548 | D35: 4
A36: Bilal Powell | B36: 131 | C36: 722 | D36: 3
A37: T.J. Yeldon | B37: 130 | C37: 465 | D37: 1
A38: Jacquizz Rodgers | B38: 129 | C38: 560 | D38: 2
A39: Matt Asiata | B39: 121 | C39: 402 | D39: 6
A40: Tevin Coleman | B40: 118 | C40: 520 | D40: 8
... A53: Giovani Bernard | B53: 91 | C53: 337 | D53: 2
A54: Rushing
A55: Player | B55: Att | C55: Yds | D55: TD
A56: Cam Newton | B56: 90 | C56: 359 | D56: 5
A57: Dwayne Washington | B57: 90 | C57: 265 | D57: 1
A58: Kenneth Dixon | B58: 88 | C58: 382 | D58: 2
A59: Charcandrick West | B59: 88 | C59: 293 | D59: 1
A60: Zach Zenner | B60: 88 | C60: 334 | D60: 4
A61: DeAndre Washington | B61: 87 | C61: 467 | D61: 2
A62: Justin Forsett | B62: 87 | C62: 291 | D62: 1
A63: Justin Forsett | B63: 31 | C63: 98 | D63: 0
A64: Justin Forsett | B64: 13 | C64: 38 | D64: 0
...

Sheet 2015
A2: Player | B2: Att | C2: Yds | D2: TD
A3: Adrian Peterson | B3: 327 | C3: 1485 | D3: 11
A4: Doug Martin | B4: 288 | C4: 1402 | D4: 6
A5: Latavius Murray | B5: 266 | C5: 1066 | D5: 6
A6: Devonta Freeman | B6: 265 | C6: 1056 | D6: 11
A7: Frank Gore | B7: 260 | C7: 967 | D7: 6
A8: Chris Ivory | B8: 247 | C8: 1070 | D8: 7
A9: Jonathan Stewart | B9: 242 | C9: 989 | D9: 6
A10: Darren McFadden | B10: 239 | C10: 1089 | D10: 3
A11: Todd Gurley | B11: 229 | C11: 1106 | D11: 10
A12: Jeremy Hill | B12: 223 | C12: 794 | D12: 11
A13: Matt Forte | B13: 218 | C13: 898 | D13: 4
A14: Ronnie Hillman | B14: 207 | C14: 863 | D14: 7
... A27: Mark Ingram | B27: 166 | C27: 769 | D27: 6
A28: Rushing
A29: Player | B29: Att | C29: Yds | D29: TD
A30: LeGarrette Blount | B30: 165 | C30: 703 | D30: 6
A31: Charcandrick West | B31: 160 | C31: 634 | D31: 4
A32: Giovani Bernard | B32: 154 | C32: 730 | D32: 2
A33: C.J. Anderson | B33: 152 | C33: 720 | D33: 5
A34: Justin Forsett | B34: 151 | C34: 641 | D34: 2
A35: Jeremy Langford | B35: 148 | C35: 537 | D35: 6
A36: James Starks | B36: 148 | C36: 601 | D36: 2
A37: Thomas Rawls | B37: 147 | C37: 830 | D37: 4
A38: Matt Jones | B38: 144 | C38: 490 | D38: 3
A39: Ameer Abdullah | B39: 143 | C39: 597 | D39: 2
A40: Antonio Andrews | B40: 143 | C40: 520 | D40: 3
A41: Javorius Allen | B41: 137 | C41: 514 | D41: 1
... A54: Tim Hightower | B54: 96 | C54: 375 | D54: 4
A55: Rushing
A56: Player | B56: Att | C56: Yds | D56: TD
A57: Karlos Williams | B57: 93 | C57: 517 | D57: 7
A58: Joique Bell | B58: 90 | C58: 311 | D58: 4
A59: Andre Williams | B59: 88 | C59: 257 | D59: 1
A60: Tevin Coleman | B60: 87 | C60: 392 | D60: 1
A61: Alex Smith | B61: 84 | C61: 498 | D61: 2
A62: Darren Sproles | B62: 83 | C62: 317 | D62: 3
A63: Shaun Draughn | B63: 78 | C63: 273 | D63: 1
A64: Shaun Draughn | B64: 2 | C64: 10 | D64: 0
A65: Shaun Draughn | B65: 76 | C65: 263 | D65: 1
...

Sheet 2014
A1: Player | B1: Att | C1: Yds | D1: TD
A2: DeMarco Murray | B2: 392 | C2: 1845 | D2: 13
A3: LeSean McCoy | B3: 312 | C3: 1319 | D3: 5
A4: Le'Veon Bell | B4: 290 | C4: 1361 | D4: 8
A5: Marshawn Lynch | B5: 280 | C5: 1306 | D5: 13
A6: Matt Forte | B6: 266 | C6: 1038 | D6: 6
A7: Alfred Morris | B7: 265 | C7: 1074 | D7: 8
A8: Arian Foster | B8: 260 | C8: 1246 | D8: 8
A9: Frank Gore | B9: 255 | C9: 1106 | D9: 4
A10: Eddie Lacy | B10: 246 | C10: 1139 | D10: 9
A11: Justin Forsett | B11: 235 | C11: 1266 | D11: 8
A12: Mark Ingram | B12: 226 | C12: 964 | D12: 9
A13: Joique Bell | B13: 223 | C13: 860 | D13: 7
... A26: Giovani Bernard | B26: 168 | C26: 680 | D26: 5
A27: Rushing
A28: Player | B28: Att | C28: Yds | D28: TD
A29: Rashad Jennings | B29: 167 | C29: 639 | D29: 4
A30: Matt Asiata | B30: 164 | C30: 570 | D30: 9
A31: Branden Oliver | B31: 160 | C31: 582 | D31: 3
A32: Trent Richardson | B32: 159 | C32: 519 | D32: 3
A33: Chris Johnson | B33: 155 | C33: 663 | D33: 1
A34: Darren McFadden | B34: 155 | C34: 534 | D34: 2
A35: Bishop Sankey | B35: 152 | C35: 569 | D35: 2
A36: Isaiah Crowell | B36: 148 | C36: 607 | D36: 8
A37: Fred Jackson | B37: 141 | C37: 525 | D37: 2
A38: Denard Robinson | B38: 135 | C38: 582 | D38: 4
A39: Knile Davis | B39: 134 | C39: 463 | D39: 6
A40: Doug Martin | B40: 134 | C40: 494 | D40: 2
... A53: Toby Gerhart | B53: 101 | C53: 326 | D53: 2
A54: Rushing
A55: Player | B55: Att | C55: Yds | D55: TD
A56: Shane Vereen | B56: 96 | C56: 391 | D56: 2
A57: Shonn Greene | B57: 94 | C57: 392 | D57: 2
A58: Bobby Rainey | B58: 94 | C58: 406 | D58: 1
A59: Stevan Ridley | B59: 94 | C59: 340 | D59: 2
A60: Bernard Pierce | B60: 93 | C60: 366 | D60: 2
A61: Ahmad Bradshaw | B61: 90 | C61: 425 | D61: 2
A62: Jonas Gray | B62: 89 | C62: 412 | D62: 5
A63: Donald Brown | B63: 85 | C63: 223 | D63: 0
A64: James Starks | B64: 85 | C64: 333 | D64: 2
...

Sheet 2013
A1: Rushing
A2: Player | B2: Att | C2: Yds | D2: TD
A3: LeSean McCoy | B3: 314 | C3: 1607 | D3: 9
A4: Marshawn Lynch | B4: 301 | C4: 1257 | D4: 12
A5: Matt Forte | B5: 289 | C5: 1339 | D5: 9
A6: Ryan Mathews | B6: 285 | C6: 1255 | D6: 6
A7: Eddie Lacy | B7: 284 | C7: 1178 | D7: 11
A8: Chris Johnson | B8: 279 | C8: 1077 | D8: 6
A9: Adrian Peterson | B9: 279 | C9: 1266 | D9: 10
A10: Frank Gore | B10: 276 | C10: 1128 | D10: 9
A11: Alfred Morris | B11: 276 | C11: 1275 | D11: 7
A12: Jamaal Charles | B12: 259 | C12: 1287 | D12: 12
A13: Zac Stacy | B13: 250 | C13: 973 | D13: 7
A14: Le'Veon Bell | B14: 244 | C14: 860 | D14: 8
... A54: Danny Woodhead | B54: 106 | C54: 429 | D54: 2
A55: Rushing
A56: Player | B56: Att | C56: Yds | D56: TD
A57: Donald Brown | B57: 102 | C57: 537 | D57: 6
A58: Mike Tolbert | B58: 101 | C58: 361 | D58: 5
A59: Jacquizz Rodgers | B59: 96 | C59: 332 | D59: 2
A60: Russell Wilson | B60: 96 | C60: 539 | D60: 1
A61: Colin Kaepernick | B61: 92 | C61: 524 | D61: 4
A62: James Starks | B62: 89 | C62: 493 | D62: 3
A63: Robert Griffin | B63: 86 | C63: 489 | D63: 0
A64: Terrelle Pryor | B64: 83 | C64: 576 | D64: 2
A65: Kendall Hunter | B65: 78 | C65: 358 | D65: 3
A66: Mark Ingram | B66: 78 | C66: 386 | D66: 1
A67: Shonn Greene | B67: 77 | C67: 295 | D67: 4
A68: Robert Turbin | B68: 77 | C68: 264 | D68: 0
... A81: Brandon Jacobs | B81: 58 | C81: 238 | D81: 4
A82: Rushing
A83: Player | B83: Att | C83: Yds | D83: TD
A84: Nick Foles | B84: 57 | C84: 221 | D84: 3
A85: Brandon Bolden | B85: 55 | C85: 271 | D85: 3
A86: Ronnie Hillman | B86: 55 | C86: 218 | D86: 1
A87: Joseph Randle | B87: 54 | C87: 164 | D87: 2
A88: Khiry Robinson | B88: 54 | C88: 224 | D88: 1
A89: EJ Manuel | B89: 53 | C89: 186 | D89: 2
A90: Darren Sproles | B90: 53 | C90: 220 | D90: 2
A91: Jonathan Dwyer | B91: 49 | C91: 197 | D91: 0
...

Sheet 2012
A1: Player | B1: Att | C1: Yds | D1: TD
A2: Brad Smith | B2: 14 | C2: 116 | D2: 1
A3: Percy Harvin | B3: 22 | C3: 96 | D3: 1
A4: Darius Reynaud | B4: 16 | C4: 33 | D4: 0
A5: Randall Cobb | B5: 10 | C5: 132 | D5: 0
A6: Nate Burleson | B6: 8 | C6: 48 | D6: 0
A7: Brandon Banks | B7: 7 | C7: 36 | D7: 0
A8: Antonio Brown | B8: 7 | C8: 24 | D8: 0
A9: Mike Thomas | B9: 7 | C9: 57 | D9: 0
A10: Travis Benjamin | B10: 6 | C10: 66 | D10: 0
A11: Josh Cribbs | B11: 6 | C11: 42 | D11: 0
A12: Andrew Hawkins | B12: 6 | C12: 30 | D12: 0
A13: Julio Jones | B13: 6 | C13: 30 | D13: 0
... A492: Matt Tennant | B492: 0 | C492: 0 | D492: 0
A493: League Average
